<?xml version="1.0" ?>
<!-- =================================================================================== -->
<!-- |    This document was autogenerated by xacro from sisbot.xacro                   | -->
<!-- |    EDITING THIS FILE BY HAND IS NOT RECOMMENDED                                 | -->
<!-- =================================================================================== -->
<robot name="ur5_robotiq_85" xmlns:xacro="http://ros.org/wiki/xacro">
  <!--################################################
  ########              arm                    #######
  ####################################################-->

  <link name="base_link">
    <visual>
      <geometry>
        <mesh filename="../meshes/ur5/visual/base.obj"/>
      </geometry>
      <material name="LightGrey">
        <color rgba="0.7 0.7 0.7 1.0"/>
      </material>
    </visual>
    <collision>
      <geometry>
        <mesh filename="../meshes/ur5/collision/base.stl"/>
      </geometry>
    </collision>
    <inertial>
      <mass value="4.0"/>
      <origin rpy="0 0 0" xyz="0.0 0.0 0.0"/>
      <inertia ixx="0.00443333156" ixy="0.0" ixz="0.0" iyy="0.00443333156" iyz="0.0" izz="0.0072"/>
    </inertial>
  </link>

  <joint name="shoulder_pan_joint" type="revolute">
    <parent link="base_link"/>
    <child link="shoulder_link"/>
    <origin rpy="0.0 0.0 0.0" xyz="0.0 0.0 0.089159"/>
    <axis xyz="0 0 1"/>
    <limit effort="150.0" lower="-3.14159265359" upper="3.14159265359" velocity="3.15"/>
    <dynamics damping="0.0" friction="0.0"/>
  </joint>
  <link name="shoulder_link">
    <visual>
      <geometry>
        <mesh filename="../meshes/ur5/visual/shoulder.obj"/>
      </geometry>
      <material name="UR-Blue">
        <color rgba="0.376 0.576 0.674 1.0"/>
      </material>
    </visual>
    <collision>
      <geometry>
        <mesh filename="../meshes/ur5/collision/shoulder.stl"/>
      </geometry>
    </collision>
    <inertial>
      <mass value="3.7"/>
      <origin rpy="0 0 0" xyz="0.0 0.0 0.0"/>
      <inertia ixx="0.010267495893" ixy="0.0" ixz="0.0" iyy="0.010267495893" iyz="0.0" izz="0.00666"/>
    </inertial>
  </link>
  <joint name="shoulder_lift_joint" type="revolute">
    <parent link="shoulder_link"/>
    <child link="upper_arm_link"/>
    <origin rpy="0.0 1.57079632679 0.0" xyz="0.0 0.13585 0.0"/>
    <axis xyz="0 1 0"/>
    <limit effort="150.0" lower="-3.14159265359" upper="3.14159265359" velocity="3.15"/>
    <dynamics damping="0.0" friction="0.0"/>
  </joint>
  <link name="upper_arm_link">
    <visual>
      <geometry>
        <mesh filename="../meshes/ur5/visual/upperarm.obj"/>
      </geometry>
      <material name="LightGrey">
        <color rgba="0.7 0.7 0.7 1.0"/>
      </material>
    </visual>
    <collision>
      <geometry>
        <mesh filename="../meshes/ur5/collision/upperarm.stl"/>
      </geometry>
    </collision>
    <inertial>
      <mass value="8.393"/>
      <origin rpy="0 0 0" xyz="0.0 0.0 0.28"/>
      <inertia ixx="0.22689067591" ixy="0.0" ixz="0.0" iyy="0.22689067591" iyz="0.0" izz="0.0151074"/>
    </inertial>
  </link>
  <joint name="elbow_joint" type="revolute">
    <parent link="upper_arm_link"/>
    <child link="forearm_link"/>
    <origin rpy="0.0 0.0 0.0" xyz="0.0 -0.1197 0.425"/>
    <axis xyz="0 1 0"/>
    <limit effort="150.0" lower="-3.14159265359" upper="3.14159265359" velocity="3.15"/>
    <dynamics damping="0.0" friction="0.0"/>
  </joint>
  <link name="forearm_link">
    <visual>
      <geometry>
        <mesh filename="../meshes/ur5/visual/forearm.obj"/>
      </geometry>
      <material name="LightGrey">
        <color rgba="0.7 0.7 0.7 1.0"/>
      </material>
    </visual>
    <collision>
      <geometry>
        <mesh filename="../meshes/ur5/collision/forearm.stl"/>
      </geometry>
    </collision>
    <inertial>
      <mass value="2.275"/>
      <origin rpy="0 0 0" xyz="0.0 0.0 0.25"/>
      <inertia ixx="0.049443313556" ixy="0.0" ixz="0.0" iyy="0.049443313556" iyz="0.0" izz="0.004095"/>
    </inertial>
  </link>
  <joint name="wrist_1_joint" type="revolute">
    <parent link="forearm_link"/>
    <child link="wrist_1_link"/>
    <origin rpy="0.0 1.57079632679 0.0" xyz="0.0 0.0 0.39225"/>
    <axis xyz="0 1 0"/>
    <limit effort="28.0" lower="-3.14159265359" upper="3.14159265359" velocity="3.2"/>
    <dynamics damping="0.0" friction="0.0"/>
  </joint>
  <link name="wrist_1_link">
    <visual>
      <geometry>
        <mesh filename="../meshes/ur5/visual/wrist1.obj"/>
      </geometry>
      <material name="UR-Blue">
        <color rgba="0.376 0.576 0.674 1.0"/>
      </material>
    </visual>
    <collision>
      <geometry>
        <mesh filename="../meshes/ur5/collision/wrist1.stl"/>
      </geometry>
    </collision>
    <inertial>
      <mass value="1.219"/>
      <origin rpy="0 0 0" xyz="0.0 0.0 0.0"/>
      <inertia ixx="0.111172755531" ixy="0.0" ixz="0.0" iyy="0.111172755531" iyz="0.0" izz="0.21942"/>
    </inertial>
  </link>
  <joint name="wrist_2_joint" type="revolute">
    <parent link="wrist_1_link"/>
    <child link="wrist_2_link"/>
    <origin rpy="0.0 0.0 0.0" xyz="0.0 0.093 0.0"/>
    <axis xyz="0 0 1"/>
    <limit effort="28.0" lower="-3.14159265359" upper="3.14159265359" velocity="3.2"/>
    <dynamics damping="0.0" friction="0.0"/>
  </joint>
  <link name="wrist_2_link">
    <visual>
      <geometry>
        <mesh filename="../meshes/ur5/visual/wrist2.obj"/>
      </geometry>
      <material name="DarkGray">
        <color rgba="0.5 0.5 0.5 1.0"/>
      </material>
    </visual>
    <collision>
      <geometry>
        <mesh filename="../meshes/ur5/collision/wrist2.stl"/>
      </geometry>
    </collision>
    <inertial>
      <mass value="1.219"/>
      <origin rpy="0 0 0" xyz="0.0 0.0 0.0"/>
      <inertia ixx="0.111172755531" ixy="0.0" ixz="0.0" iyy="0.111172755531" iyz="0.0" izz="0.21942"/>
    </inertial>
  </link>
  <joint name="wrist_3_joint" type="revolute">
    <parent link="wrist_2_link"/>
    <child link="wrist_3_link"/>
    <origin rpy="0.0 0.0 0.0" xyz="0.0 0.0 0.09465"/>
    <axis xyz="0 1 0"/>
    <limit effort="28.0" lower="-3.14159265359" upper="3.14159265359" velocity="3.2"/>
    <dynamics damping="0.0" friction="0.0"/>
  </joint>
  <link name="wrist_3_link">
    <visual>
      <geometry>
        <mesh filename="../meshes/ur5/visual/wrist3.obj"/>
      </geometry>
      <material name="LightGrey">
        <color rgba="0.7 0.7 0.7 1.0"/>
      </material>
    </visual>
    <collision>
      <geometry>
        <mesh filename="../meshes/ur5/collision/wrist3.stl"/>
      </geometry>
    </collision>
    <inertial>
      <mass value="0.1879"/>
      <origin rpy="0 0 0" xyz="0.0 0.0 0.0"/>
      <inertia ixx="0.0171364731454" ixy="0.0" ixz="0.0" iyy="0.0171364731454" iyz="0.0" izz="0.033822"/>
    </inertial>
  </link>
  <joint name="ee_fixed_joint" type="fixed">
    <parent link="wrist_3_link"/>
    <child link="ee_link"/>
    <origin rpy="0.0 0.0 1.57079632679" xyz="0.0 0.0823 0.0"/>
  </joint>
  <link name="ee_link">
    <collision>
      <geometry>
        <box size="0.01 0.01 0.01"/>
      </geometry>
      <origin rpy="0 0 0" xyz="-0.01 0 0"/>
    </collision>
  </link>

  <!-- ################################################
  ########          Robotiq 85 Gripper          #######
  #################################################### -->

  <joint name="robotiq_85_base_joint" type="fixed">
    <parent link="ee_link"/>
    <child link="robotiq_85_base_link"/>
    <origin rpy="0.0 0.0 0.0" xyz="0.0 0.0 0.0"/>
  </joint>
  <link name="robotiq_85_base_link">
    <visual>
      <geometry>
        <mesh filename="../meshes/robotiq_85/visual/robotiq_arg2f_85_base_link.dae"/>
      </geometry>
    </visual>
    <collision>
      <geometry>
        <mesh filename="../meshes/robotiq_85/collision/robotiq_arg2f_85_base_link.stl"/>
      </geometry>
    </collision>
    <inertial>
      <mass value="0.636951"/>
      <origin rpy="0 0 0" xyz="0.0 0.0 0.0"/>
      <inertia ixx="0.000380" ixy="0.0" ixz="0.0" iyy="0.001110" iyz="0.0" izz="0.001171"/>
    </inertial>
  </link>

  <!-- Left outer knuckle -->
  <joint name="finger_joint" type="revolute">
    <parent link="robotiq_85_base_link"/>
    <child link="robotiq_85_left_outer_knuckle"/>
    <origin rpy="0.0 0.0 0.0" xyz="-0.0306011 0.0 0.054904"/>
    <axis xyz="0 1 0"/>
    <limit effort="50" lower="0.0" upper="0.8" velocity="0.5"/>
    <dynamics damping="0.1" friction="0.0"/>
  </joint>
  <link name="robotiq_85_left_outer_knuckle">
    <visual>
      <geometry>
        <mesh filename="../meshes/robotiq_85/visual/robotiq_arg2f_85_outer_knuckle.dae"/>
      </geometry>
    </visual>
    <collision>
      <geometry>
        <mesh filename="../meshes/robotiq_85/collision/robotiq_arg2f_85_outer_knuckle.dae.convex.stl"/>
      </geometry>
    </collision>
    <inertial>
      <mass value="0.018491"/>
      <origin rpy="0 0 0" xyz="0.0 0.0 0.0"/>
      <inertia ixx="0.000009" ixy="0.0" ixz="0.0" iyy="0.000009" iyz="0.0" izz="0.000015"/>
    </inertial>
  </link>

  <!-- Left outer finger -->
  <joint name="left_outer_finger_joint" type="fixed">
    <parent link="robotiq_85_left_outer_knuckle"/>
    <child link="robotiq_85_left_outer_finger"/>
    <origin rpy="0.0 0.0 0.0" xyz="0.0 0.0 0.0"/>
  </joint>
  <link name="robotiq_85_left_outer_finger">
    <visual>
      <geometry>
        <mesh filename="../meshes/robotiq_85/visual/robotiq_arg2f_85_outer_finger.dae"/>
      </geometry>
    </visual>
    <collision>
      <geometry>
        <mesh filename="../meshes/robotiq_85/collision/robotiq_arg2f_85_outer_finger.dae.convex.stl"/>
      </geometry>
    </collision>
    <inertial>
      <mass value="0.027309"/>
      <origin rpy="0 0 0" xyz="0.0 0.0 0.0"/>
      <inertia ixx="0.000028" ixy="0.0" ixz="0.0" iyy="0.000025" iyz="0.0" izz="0.000009"/>
    </inertial>
  </link>

  <!-- Left inner knuckle -->
  <joint name="left_inner_knuckle_joint" type="revolute">
    <parent link="robotiq_85_base_link"/>
    <child link="robotiq_85_left_inner_knuckle"/>
    <origin rpy="0.0 0.0 0.0" xyz="-0.0127 0.0 0.06142"/>
    <axis xyz="0 1 0"/>
    <limit effort="50" lower="0.0" upper="0.8" velocity="0.5"/>
    <mimic joint="finger_joint" multiplier="1" offset="0"/>
    <dynamics damping="0.1" friction="0.0"/>
  </joint>
  <link name="robotiq_85_left_inner_knuckle">
    <visual>
      <geometry>
        <mesh filename="../meshes/robotiq_85/visual/robotiq_arg2f_85_inner_knuckle.dae"/>
      </geometry>
    </visual>
    <collision>
      <geometry>
        <mesh filename="../meshes/robotiq_85/collision/robotiq_arg2f_85_inner_knuckle.dae.convex.stl"/>
      </geometry>
    </collision>
    <inertial>
      <mass value="0.029951"/>
      <origin rpy="0 0 0" xyz="0.0 0.0 0.0"/>
      <inertia ixx="0.000039" ixy="0.0" ixz="0.0" iyy="0.000031" iyz="0.0" izz="0.000015"/>
    </inertial>
  </link>

  <!-- Left inner finger -->
  <joint name="left_inner_finger_joint" type="revolute">
    <parent link="robotiq_85_left_outer_knuckle"/>
    <child link="robotiq_85_left_inner_finger"/>
    <origin rpy="0.0 0.0 0.0" xyz="0.0 0.0 0.09585"/>
    <axis xyz="0 1 0"/>
    <limit effort="50" lower="-0.8" upper="0.0" velocity="0.5"/>
    <mimic joint="finger_joint" multiplier="-1" offset="0"/>
    <dynamics damping="0.1" friction="0.0"/>
  </joint>
  <link name="robotiq_85_left_inner_finger">
    <visual>
      <geometry>
        <mesh filename="../meshes/robotiq_85/visual/robotiq_arg2f_85_inner_finger.dae"/>
      </geometry>
    </visual>
    <collision>
      <geometry>
        <mesh filename="../meshes/robotiq_85/collision/robotiq_arg2f_85_inner_finger.dae.convex.stl"/>
      </geometry>
    </collision>
    <inertial>
      <mass value="0.019555"/>
      <origin rpy="0 0 0" xyz="0.0 0.0 0.0"/>
      <inertia ixx="0.000003" ixy="0.0" ixz="0.0" iyy="0.000021" iyz="0.0" izz="0.000020"/>
    </inertial>
  </link>

  <!-- Right outer knuckle -->
  <joint name="right_outer_knuckle_joint" type="revolute">
    <parent link="robotiq_85_base_link"/>
    <child link="robotiq_85_right_outer_knuckle"/>
    <origin rpy="0.0 3.14159265359 0.0" xyz="0.0306011 0.0 0.054904"/>
    <axis xyz="0 1 0"/>
    <limit effort="50" lower="0.0" upper="0.8" velocity="0.5"/>
    <mimic joint="finger_joint" multiplier="1" offset="0"/>
    <dynamics damping="0.1" friction="0.0"/>
  </joint>
  <link name="robotiq_85_right_outer_knuckle">
    <visual>
      <geometry>
        <mesh filename="../meshes/robotiq_85/visual/robotiq_arg2f_85_outer_knuckle.dae"/>
      </geometry>
    </visual>
    <collision>
      <geometry>
        <mesh filename="../meshes/robotiq_85/collision/robotiq_arg2f_85_outer_knuckle.dae.convex.stl"/>
      </geometry>
    </collision>
    <inertial>
      <mass value="0.018491"/>
      <origin rpy="0 0 0" xyz="0.0 0.0 0.0"/>
      <inertia ixx="0.000009" ixy="0.0" ixz="0.0" iyy="0.000009" iyz="0.0" izz="0.000015"/>
    </inertial>
  </link>

  <!-- Right outer finger -->
  <joint name="right_outer_finger_joint" type="fixed">
    <parent link="robotiq_85_right_outer_knuckle"/>
    <child link="robotiq_85_right_outer_finger"/>
    <origin rpy="0.0 0.0 0.0" xyz="0.0 0.0 0.0"/>
  </joint>
  <link name="robotiq_85_right_outer_finger">
    <visual>
      <geometry>
        <mesh filename="../meshes/robotiq_85/visual/robotiq_arg2f_85_outer_finger.dae"/>
      </geometry>
    </visual>
    <collision>
      <geometry>
        <mesh filename="../meshes/robotiq_85/collision/robotiq_arg2f_85_outer_finger.dae.convex.stl"/>
      </geometry>
    </collision>
    <inertial>
      <mass value="0.027309"/>
      <origin rpy="0 0 0" xyz="0.0 0.0 0.0"/>
      <inertia ixx="0.000028" ixy="0.0" ixz="0.0" iyy="0.000025" iyz="0.0" izz="0.000009"/>
    </inertial>
  </link>

  <!-- Right inner knuckle -->
  <joint name="right_inner_knuckle_joint" type="revolute">
    <parent link="robotiq_85_base_link"/>
    <child link="robotiq_85_right_inner_knuckle"/>
    <origin rpy="0.0 3.14159265359 0.0" xyz="0.0127 0.0 0.06142"/>
    <axis xyz="0 1 0"/>
    <limit effort="50" lower="0.0" upper="0.8" velocity="0.5"/>
    <mimic joint="finger_joint" multiplier="1" offset="0"/>
    <dynamics damping="0.1" friction="0.0"/>
  </joint>
  <link name="robotiq_85_right_inner_knuckle">
    <visual>
      <geometry>
        <mesh filename="../meshes/robotiq_85/visual/robotiq_arg2f_85_inner_knuckle.dae"/>
      </geometry>
    </visual>
    <collision>
      <geometry>
        <mesh filename="../meshes/robotiq_85/collision/robotiq_arg2f_85_inner_knuckle.dae.convex.stl"/>
      </geometry>
    </collision>
    <inertial>
      <mass value="0.029951"/>
      <origin rpy="0 0 0" xyz="0.0 0.0 0.0"/>
      <inertia ixx="0.000039" ixy="0.0" ixz="0.0" iyy="0.000031" iyz="0.0" izz="0.000015"/>
    </inertial>
  </link>

  <!-- Right inner finger -->
  <joint name="right_inner_finger_joint" type="revolute">
    <parent link="robotiq_85_right_outer_knuckle"/>
    <child link="robotiq_85_right_inner_finger"/>
    <origin rpy="0.0 0.0 0.0" xyz="0.0 0.0 0.09585"/>
    <axis xyz="0 1 0"/>
    <limit effort="50" lower="-0.8" upper="0.0" velocity="0.5"/>
    <mimic joint="finger_joint" multiplier="-1" offset="0"/>
    <dynamics damping="0.1" friction="0.0"/>
  </joint>
  <link name="robotiq_85_right_inner_finger">
    <visual>
      <geometry>
        <mesh filename="../meshes/robotiq_85/visual/robotiq_arg2f_85_inner_finger.dae"/>
      </geometry>
    </visual>
    <collision>
      <geometry>
        <mesh filename="../meshes/robotiq_85/collision/robotiq_arg2f_85_inner_finger.dae.convex.stl"/>
      </geometry>
    </collision>
    <inertial>
      <mass value="0.019555"/>
      <origin rpy="0 0 0" xyz="0.0 0.0 0.0"/>
      <inertia ixx="0.000003" ixy="0.0" ixz="0.0" iyy="0.000021" iyz="0.0" izz="0.000020"/>
    </inertial>
  </link>

  <!-- Gripper tip (grasp reference point) -->
  <joint name="gripper_tip_joint" type="fixed">
    <parent link="robotiq_85_base_link"/>
    <child link="gripper_tip_link"/>
    <origin rpy="0.0 0.0 0.0" xyz="0.0 0.0 0.145"/>
  </joint>
  <link name="gripper_tip_link"/>

  <!-- ################################################
  ########        Eye-in-Hand Camera           #######
  #################################################### -->

  <joint name="camera_joint" type="fixed">
    <parent link="robotiq_85_base_link"/>
    <child link="camera_link"/>
    <!-- mounted above gripper base, pointing downward toward target -->
    <origin rpy="0.0 1.57079632679 0.0" xyz="0.0 0.0 -0.05"/>
  </joint>
  <link name="camera_link">
    <visual>
      <geometry>
        <box size="0.02 0.02 0.02"/>
      </geometry>
      <material name="CameraBlack">
        <color rgba="0.1 0.1 0.1 1.0"/>
      </material>
    </visual>
    <inertial>
      <mass value="0.01"/>
      <origin rpy="0 0 0" xyz="0 0 0"/>
      <inertia ixx="0.0" ixy="0.0" ixz="0.0" iyy="0.0" iyz="0.0" izz="0.0"/>
    </inertial>
  </link>

</robot>


